<?xml version="1.0" ?>
<!-- =================================================================================== -->
<!-- |    This document was autogenerated by xacro from transformable_bot.urdf.xacro   | -->
<!-- |    EDITING THIS FILE BY HAND IS NOT RECOMMENDED                                 | -->
<!-- =================================================================================== -->
<robot name="transformable_bot">
  <!-- Material Definations -->
  <material name="blue">
    <color rgba="0 0.5 1 1"/>
  </material>
  <material name="orange">
    <color rgba="1 0.5 0 1"/>
  </material>
  <material name="green">
    <color rgba="0.5 1 0 1"/>
  </material>
  <!-- Propeller Materials -->
  <material name="propeller_cw">
    <color rgba="0.2 0.9 0.9 0.8"/>
    <!-- Dark Gray cw-->
  </material>
  <material name="propeller_ccw">
    <color rgba="0.8 0.8 0.8 0.8"/>
    <!-- Light gray ccw-->
  </material>
  <!-- Motor and Gimbal Materials -->
  <material name="motor_material">
    <color rgba="0.15 0.15 0.15 1.0"/>
    <!-- Dark motor -->
  </material>
  <material name="gimbal_material">
    <color rgba="0.4 0.4 0.5 1.0"/>
    <!-- Metallic gimbal -->
  </material>
  <material name="rim_material">
    <color rgba="0.7 0.7 0.8 0.9"/>
    <!-- Protective rim -->
  </material>
  <material name="wheel_material">
    <color rgba="0.1 0.1 0.1 1.0"/>
    <!-- Black tire -->
  </material>
  <!-- Main Body Link -->
  <link name="base_link">
    <!-- Visual (what you see) -->
    <visual>
      <origin rpy="0 0 0" xyz="0 0 0"/>
      <geometry>
        <box size="0.3 0.2 0.1"/>
      </geometry>
      <material name="blue"/>
    </visual>
    <!-- Collision (for physics) -->
    <collision>
      <origin rpy="0 0 0" xyz="0 0 0"/>
      <geometry>
        <box size="0.3 0.2 0.1"/>
      </geometry>
    </collision>
    <!-- Inertial (for physic simulation) -->
    <inertial>
      <mass value="2.0"/>
      <inertia ixx="0.01" ixy="0" ixz="0" iyy="0.01" iyz="0" izz="0.01"/>
    </inertial>
  </link>
  <!--ARM 1: Front-Right (45 degrees)-->
  <link name="front_right_arm">
    <!-- Visual -->
    <visual>
      <origin rpy="0 0 0 " xyz="0 0 0"/>
      <geometry>
        <box size="0.4 0.015 0.015"/>
      </geometry>
      <material name="orange"/>
    </visual>
    <!-- Collision -->
    <collision>
      <origin rpy="0 0 0" xyz="0 0 0"/>
      <geometry>
        <box size="0.4 0.015 0.015"/>
      </geometry>
    </collision>
    <!-- Inertial -->
    <inertial>
      <origin rpy="0 0 0" xyz="0 0 0"/>
      <mass value="0.2"/>
      <inertia ixx="0.001" ixy="0" ixz="0" iyy="0.001" iyz="0" izz="0.001"/>
    </inertial>
  </link>
  <!-- Joint Connecting Body to Arm -->
  <joint name="base_to_front_right_arm" type="fixed">
    <parent link="base_link"/>
    <child link="front_right_arm"/>
    <origin rpy="0 0 0.7853981633974483" xyz="0.05656854249492381 0.056568542494923796 0"/>
  </joint>
  <!-- ARM 2: Back-Right (135 degrees) -->
  <link name="back_right_arm">
    <visual>
      <origin rpy="0 0 0" xyz="0 0 0"/>
      <geometry>
        <box size="0.4 0.015 0.015"/>
      </geometry>
      <material name="green"/>
    </visual>
    <collision>
      <origin rpy="0 0 0" xyz="0 0 0"/>
      <geometry>
        <box size="0.4 0.015 0.015"/>
      </geometry>
    </collision>
    <inertial>
      <origin rpy="0 0 0" xyz="0 0 0"/>
      <mass value="0.2"/>
      <inertia ixx="0.001" ixy="0" ixz="0" iyy="0.001" iyz="0" izz="0.001"/>
    </inertial>
  </link>
  <joint name="base_to_back_right_arm" type="fixed">
    <parent link="base_link"/>
    <child link="back_right_arm"/>
    <origin rpy="0 0 2.356194490192345" xyz="-0.056568542494923796 0.05656854249492381 0"/>
  </joint>
  <!-- ARM 3: Back-Left (225 degrees) -->
  <link name="back_left_arm">
    <visual>
      <origin rpy="0 0 0" xyz="0 0 0"/>
      <geometry>
        <box size="0.4 0.015 0.015"/>
      </geometry>
      <material name="orange"/>
    </visual>
    <collision>
      <origin rpy="0 0 0" xyz="0 0 0"/>
      <geometry>
        <box size="0.4 0.015 0.015"/>
      </geometry>
    </collision>
    <inertial>
      <origin rpy="0 0 0" xyz="0 0 0"/>
      <mass value="0.2"/>
      <inertia ixx="0.001" ixy="0" ixz="0" iyy="0.001" iyz="0" izz="0.001"/>
    </inertial>
  </link>
  <joint name="base_to_back_left_arm" type="fixed">
    <parent link="base_link"/>
    <child link="back_left_arm"/>
    <origin rpy="0 0 3.9269908169872414" xyz="-0.05656854249492382 -0.056568542494923796 0"/>
  </joint>
  <!-- ARM 4: Front-Left (315 degrees) -->
  <link name="front_left_arm">
    <visual>
      <origin rpy="0 0 0" xyz="0 0 0"/>
      <geometry>
        <box size="0.4 0.015 0.015"/>
      </geometry>
      <material name="green"/>
    </visual>
    <collision>
      <origin rpy="0 0 0" xyz="0 0 0"/>
      <geometry>
        <box size="0.4 0.015 0.015"/>
      </geometry>
    </collision>
    <inertial>
      <origin rpy="0 0 0" xyz="0 0 0"/>
      <mass value="0.2"/>
      <inertia ixx="0.001" ixy="0" ixz="0" iyy="0.001" iyz="0" izz="0.001"/>
    </inertial>
  </link>
  <joint name="base_to_front_left_arm" type="fixed">
    <parent link="base_link"/>
    <child link="front_left_arm"/>
    <origin rpy="0 0 5.497787143782138" xyz="0.05656854249492379 -0.05656854249492382 0"/>
  </joint>
  <!-- Gimbal Base (attached to arm) -->
  <link name="front_right_gimbal_base">
    <visual>
      <geometry>
        <cylinder length="0.02" radius="0.03"/>
      </geometry>
      <material name="gimbal_material"/>
    </visual>
    <collision>
      <geometry>
        <cylinder length="0.02" radius="0.03"/>
      </geometry>
    </collision>
    <inertial>
      <mass value="0.05"/>
      <inertia ixx="0.00005" ixy="0" ixz="0" iyy="0.00005" iyz="0" izz="0.00008"/>
    </inertial>
  </link>
  <!-- Gimbal Ring (X-axis tilt control) -->
  <link name="front_right_gimbal_ring">
    <visual>
      <geometry>
        <cylinder length="0.01" radius="0.024"/>
      </geometry>
      <material name="gimbal_material"/>
    </visual>
    <collision>
      <geometry>
        <cylinder length="0.01" radius="0.024"/>
      </geometry>
    </collision>
    <inertial>
      <mass value="0.03"/>
      <inertia ixx="0.00003" ixy="0" ixz="0" iyy="0.00003" iyz="0" izz="0.00005"/>
    </inertial>
  </link>
  <!-- Motor (final rotating element) -->
  <link name="front_right_motor">
    <visual>
      <geometry>
        <cylinder length="0.04" radius="0.025"/>
      </geometry>
      <material name="motor_material"/>
    </visual>
    <collision>
      <geometry>
        <cylinder length="0.04" radius="0.025"/>
      </geometry>
    </collision>
    <inertial>
      <origin rpy="0 0 0" xyz="0 0 0.02"/>
      <mass value="0.15"/>
      <inertia ixx="0.0001" ixy="0" ixz="0" iyy="0.0001" iyz="0" izz="0.0001"/>
    </inertial>
  </link>
  <!-- Gimbal Joints -->
  <!-- Arm to Gimbal Base (fixed mounting) -->
  <joint name="front_right_arm_to_front_right_gimbal" type="fixed">
    <parent link="front_right_arm"/>
    <child link="front_right_gimbal_base"/>
    <origin rpy="0 0 0" xyz="0.2 0 0"/>
  </joint>
  <!-- Gimbal X-axis Tilt (drone vs car mode)-->
  <joint name="front_right_gimbal_tilt" type="revolute">
    <parent link="front_right_gimbal_base"/>
    <child link="front_right_gimbal_ring"/>
    <origin rpy="0 0 0" xyz="0 0 0.01"/>
    <axis xyz="1 0 0"/>
    <limit effort="20" lower="-1.5708" upper="1.5708" velocity="1.0"/>
    <dynamics damping="0.1" friction="0.05"/>
  </joint>
  <!-- Gimbal Z-axis Rotation (thrust direction) -->
  <joint name="front_right_gimbal_rotate" type="revolute">
    <parent link="front_right_gimbal_ring"/>
    <child link="front_right_motor"/>
    <origin rpy="0 0 0" xyz="0 0 0.02"/>
    <axis xyz="0 0 1"/>
    <limit effort="20" lower="-1.5708" upper="1.5708" velocity="1.0"/>
    <dynamics damping="0.1" friction="0.05"/>
  </joint>
  <!-- Gimbal Base (attached to arm) -->
  <link name="back_right_gimbal_base">
    <visual>
      <geometry>
        <cylinder length="0.02" radius="0.03"/>
      </geometry>
      <material name="gimbal_material"/>
    </visual>
    <collision>
      <geometry>
        <cylinder length="0.02" radius="0.03"/>
      </geometry>
    </collision>
    <inertial>
      <mass value="0.05"/>
      <inertia ixx="0.00005" ixy="0" ixz="0" iyy="0.00005" iyz="0" izz="0.00008"/>
    </inertial>
  </link>
  <!-- Gimbal Ring (X-axis tilt control) -->
  <link name="back_right_gimbal_ring">
    <visual>
      <geometry>
        <cylinder length="0.01" radius="0.024"/>
      </geometry>
      <material name="gimbal_material"/>
    </visual>
    <collision>
      <geometry>
        <cylinder length="0.01" radius="0.024"/>
      </geometry>
    </collision>
    <inertial>
      <mass value="0.03"/>
      <inertia ixx="0.00003" ixy="0" ixz="0" iyy="0.00003" iyz="0" izz="0.00005"/>
    </inertial>
  </link>
  <!-- Motor (final rotating element) -->
  <link name="back_right_motor">
    <visual>
      <geometry>
        <cylinder length="0.04" radius="0.025"/>
      </geometry>
      <material name="motor_material"/>
    </visual>
    <collision>
      <geometry>
        <cylinder length="0.04" radius="0.025"/>
      </geometry>
    </collision>
    <inertial>
      <origin rpy="0 0 0" xyz="0 0 0.02"/>
      <mass value="0.15"/>
      <inertia ixx="0.0001" ixy="0" ixz="0" iyy="0.0001" iyz="0" izz="0.0001"/>
    </inertial>
  </link>
  <!-- Gimbal Joints -->
  <!-- Arm to Gimbal Base (fixed mounting) -->
  <joint name="back_right_arm_to_back_right_gimbal" type="fixed">
    <parent link="back_right_arm"/>
    <child link="back_right_gimbal_base"/>
    <origin rpy="0 0 0" xyz="0.2 0 0"/>
  </joint>
  <!-- Gimbal X-axis Tilt (drone vs car mode)-->
  <joint name="back_right_gimbal_tilt" type="revolute">
    <parent link="back_right_gimbal_base"/>
    <child link="back_right_gimbal_ring"/>
    <origin rpy="0 0 0" xyz="0 0 0.01"/>
    <axis xyz="1 0 0"/>
    <limit effort="20" lower="-1.5708" upper="1.5708" velocity="1.0"/>
    <dynamics damping="0.1" friction="0.05"/>
  </joint>
  <!-- Gimbal Z-axis Rotation (thrust direction) -->
  <joint name="back_right_gimbal_rotate" type="revolute">
    <parent link="back_right_gimbal_ring"/>
    <child link="back_right_motor"/>
    <origin rpy="0 0 0" xyz="0 0 0.02"/>
    <axis xyz="0 0 1"/>
    <limit effort="20" lower="-1.5708" upper="1.5708" velocity="1.0"/>
    <dynamics damping="0.1" friction="0.05"/>
  </joint>
  <!-- Gimbal Base (attached to arm) -->
  <link name="back_left_gimbal_base">
    <visual>
      <geometry>
        <cylinder length="0.02" radius="0.03"/>
      </geometry>
      <material name="gimbal_material"/>
    </visual>
    <collision>
      <geometry>
        <cylinder length="0.02" radius="0.03"/>
      </geometry>
    </collision>
    <inertial>
      <mass value="0.05"/>
      <inertia ixx="0.00005" ixy="0" ixz="0" iyy="0.00005" iyz="0" izz="0.00008"/>
    </inertial>
  </link>
  <!-- Gimbal Ring (X-axis tilt control) -->
  <link name="back_left_gimbal_ring">
    <visual>
      <geometry>
        <cylinder length="0.01" radius="0.024"/>
      </geometry>
      <material name="gimbal_material"/>
    </visual>
    <collision>
      <geometry>
        <cylinder length="0.01" radius="0.024"/>
      </geometry>
    </collision>
    <inertial>
      <mass value="0.03"/>
      <inertia ixx="0.00003" ixy="0" ixz="0" iyy="0.00003" iyz="0" izz="0.00005"/>
    </inertial>
  </link>
  <!-- Motor (final rotating element) -->
  <link name="back_left_motor">
    <visual>
      <geometry>
        <cylinder length="0.04" radius="0.025"/>
      </geometry>
      <material name="motor_material"/>
    </visual>
    <collision>
      <geometry>
        <cylinder length="0.04" radius="0.025"/>
      </geometry>
    </collision>
    <inertial>
      <origin rpy="0 0 0" xyz="0 0 0.02"/>
      <mass value="0.15"/>
      <inertia ixx="0.0001" ixy="0" ixz="0" iyy="0.0001" iyz="0" izz="0.0001"/>
    </inertial>
  </link>
  <!-- Gimbal Joints -->
  <!-- Arm to Gimbal Base (fixed mounting) -->
  <joint name="back_left_arm_to_back_left_gimbal" type="fixed">
    <parent link="back_left_arm"/>
    <child link="back_left_gimbal_base"/>
    <origin rpy="0 0 0" xyz="0.2 0 0"/>
  </joint>
  <!-- Gimbal X-axis Tilt (drone vs car mode)-->
  <joint name="back_left_gimbal_tilt" type="revolute">
    <parent link="back_left_gimbal_base"/>
    <child link="back_left_gimbal_ring"/>
    <origin rpy="0 0 0" xyz="0 0 0.01"/>
    <axis xyz="1 0 0"/>
    <limit effort="20" lower="-1.5708" upper="1.5708" velocity="1.0"/>
    <dynamics damping="0.1" friction="0.05"/>
  </joint>
  <!-- Gimbal Z-axis Rotation (thrust direction) -->
  <joint name="back_left_gimbal_rotate" type="revolute">
    <parent link="back_left_gimbal_ring"/>
    <child link="back_left_motor"/>
    <origin rpy="0 0 0" xyz="0 0 0.02"/>
    <axis xyz="0 0 1"/>
    <limit effort="20" lower="-1.5708" upper="1.5708" velocity="1.0"/>
    <dynamics damping="0.1" friction="0.05"/>
  </joint>
  <!-- Gimbal Base (attached to arm) -->
  <link name="front_left_gimbal_base">
    <visual>
      <geometry>
        <cylinder length="0.02" radius="0.03"/>
      </geometry>
      <material name="gimbal_material"/>
    </visual>
    <collision>
      <geometry>
        <cylinder length="0.02" radius="0.03"/>
      </geometry>
    </collision>
    <inertial>
      <mass value="0.05"/>
      <inertia ixx="0.00005" ixy="0" ixz="0" iyy="0.00005" iyz="0" izz="0.00008"/>
    </inertial>
  </link>
  <!-- Gimbal Ring (X-axis tilt control) -->
  <link name="front_left_gimbal_ring">
    <visual>
      <geometry>
        <cylinder length="0.01" radius="0.024"/>
      </geometry>
      <material name="gimbal_material"/>
    </visual>
    <collision>
      <geometry>
        <cylinder length="0.01" radius="0.024"/>
      </geometry>
    </collision>
    <inertial>
      <mass value="0.03"/>
      <inertia ixx="0.00003" ixy="0" ixz="0" iyy="0.00003" iyz="0" izz="0.00005"/>
    </inertial>
  </link>
  <!-- Motor (final rotating element) -->
  <link name="front_left_motor">
    <visual>
      <geometry>
        <cylinder length="0.04" radius="0.025"/>
      </geometry>
      <material name="motor_material"/>
    </visual>
    <collision>
      <geometry>
        <cylinder length="0.04" radius="0.025"/>
      </geometry>
    </collision>
    <inertial>
      <origin rpy="0 0 0" xyz="0 0 0.02"/>
      <mass value="0.15"/>
      <inertia ixx="0.0001" ixy="0" ixz="0" iyy="0.0001" iyz="0" izz="0.0001"/>
    </inertial>
  </link>
  <!-- Gimbal Joints -->
  <!-- Arm to Gimbal Base (fixed mounting) -->
  <joint name="front_left_arm_to_front_left_gimbal" type="fixed">
    <parent link="front_left_arm"/>
    <child link="front_left_gimbal_base"/>
    <origin rpy="0 0 0" xyz="0.2 0 0"/>
  </joint>
  <!-- Gimbal X-axis Tilt (drone vs car mode)-->
  <joint name="front_left_gimbal_tilt" type="revolute">
    <parent link="front_left_gimbal_base"/>
    <child link="front_left_gimbal_ring"/>
    <origin rpy="0 0 0" xyz="0 0 0.01"/>
    <axis xyz="1 0 0"/>
    <limit effort="20" lower="-1.5708" upper="1.5708" velocity="1.0"/>
    <dynamics damping="0.1" friction="0.05"/>
  </joint>
  <!-- Gimbal Z-axis Rotation (thrust direction) -->
  <joint name="front_left_gimbal_rotate" type="revolute">
    <parent link="front_left_gimbal_ring"/>
    <child link="front_left_motor"/>
    <origin rpy="0 0 0" xyz="0 0 0.02"/>
    <axis xyz="0 0 1"/>
    <limit effort="20" lower="-1.5708" upper="1.5708" velocity="1.0"/>
    <dynamics damping="0.1" friction="0.05"/>
  </joint>
  <!-- Propeller Hub (center) -->
  <link name="propeller_front_right_hub">
    <visual>
      <origin rpy="0 0 0" xyz="0 0 0"/>
      <geometry>
        <cylinder length="0.005" radius="0.008"/>
      </geometry>
      <material name="gimbal_material">
        <color rgba="0.1 0.1 0.1 1.0"/>
      </material>
    </visual>
    <collision>
      <origin rpy="0 0 0" xyz="0 0 0"/>
      <geometry>
        <cylinder length="0.005" radius="0.008"/>
      </geometry>
    </collision>
    <inertial>
      <origin rpy="0 0 0" xyz="0 0 0"/>
      <mass value="0.05"/>
      <inertia ixx="0.00001" ixy="0" ixz="0" iyy="0.00001" iyz="0" izz="0.00001"/>
    </inertial>
  </link>
  <!-- Blade 1-->
  <link name="propeller_front_right_blade1">
    <visual>
      <origin rpy="0 0 0" xyz="0.045 0 0"/>
      <geometry>
        <box size="0.09 0.008 0.002"/>
      </geometry>
      <material name="propeller_ccw"/>
    </visual>
    <collision>
      <origin rpy="0 0 0" xyz="0.045 0 0"/>
      <geometry>
        <box size="0.09 0.008 0.002"/>
      </geometry>
    </collision>
    <inertial>
      <origin rpy="0 0 0" xyz="0.045 0 0"/>
      <mass value="0.002"/>
      <inertia ixx="0.000001" ixy="0" ixz="0" iyy="0.000001" iyz="0" izz="0.000001"/>
    </inertial>
  </link>
  <!-- Blade 2 -->
  <link name="propeller_front_right_blade2">
    <visual>
      <origin rpy="0 0 0" xyz="-0.045 0 0"/>
      <geometry>
        <box size="0.09 0.008 0.002"/>
      </geometry>
      <material name="propeller_ccw"/>
    </visual>
    <collision>
      <origin rpy="0 0 0" xyz="-0.045 0 0"/>
      <geometry>
        <box size="0.09 0.008 0.002"/>
      </geometry>
    </collision>
    <inertial>
      <origin rpy="0 0 0" xyz="-0.045 0 0"/>
      <mass value="0.002"/>
      <inertia ixx="0.000001" ixy="0" ixz="0" iyy="0.000001" iyz="0" izz="0.000001"/>
    </inertial>
  </link>
  <!-- Joint connecting hub to blade 1 -->
  <joint name="propeller_front_right_hub_to_blade1" type="fixed">
    <parent link="propeller_front_right_hub"/>
    <child link="propeller_front_right_blade1"/>
    <origin rpy="0 0 0" xyz="0 0 0"/>
  </joint>
  <joint name="propeller_front_right_hub_to_blade2" type="fixed">
    <parent link="propeller_front_right_hub"/>
    <child link="propeller_front_right_blade2"/>
    <origin rpy="0 0 0" xyz="0 0 0"/>
  </joint>
  <joint name="front_right_motor_to_propeller" type="continuous">
    <parent link="front_right_motor"/>
    <child link="propeller_front_right_hub"/>
    <origin rpy="0 0 0" xyz="0 0 0.12000000000000001 0 0"/>
    <axis xyz="0 0 1"/>
    <dynamics damping="0.01" friction="0.001"/>
  </joint>
  <!-- Propeller Hub (center) -->
  <link name="propeller_back_right_hub">
    <visual>
      <origin rpy="0 0 0" xyz="0 0 0"/>
      <geometry>
        <cylinder length="0.005" radius="0.008"/>
      </geometry>
      <material name="gimbal_material">
        <color rgba="0.1 0.1 0.1 1.0"/>
      </material>
    </visual>
    <collision>
      <origin rpy="0 0 0" xyz="0 0 0"/>
      <geometry>
        <cylinder length="0.005" radius="0.008"/>
      </geometry>
    </collision>
    <inertial>
      <origin rpy="0 0 0" xyz="0 0 0"/>
      <mass value="0.05"/>
      <inertia ixx="0.00001" ixy="0" ixz="0" iyy="0.00001" iyz="0" izz="0.00001"/>
    </inertial>
  </link>
  <!-- Blade 1-->
  <link name="propeller_back_right_blade1">
    <visual>
      <origin rpy="0 0 0" xyz="0.045 0 0"/>
      <geometry>
        <box size="0.09 0.008 0.002"/>
      </geometry>
      <material name="propeller_cw"/>
    </visual>
    <collision>
      <origin rpy="0 0 0" xyz="0.045 0 0"/>
      <geometry>
        <box size="0.09 0.008 0.002"/>
      </geometry>
    </collision>
    <inertial>
      <origin rpy="0 0 0" xyz="0.045 0 0"/>
      <mass value="0.002"/>
      <inertia ixx="0.000001" ixy="0" ixz="0" iyy="0.000001" iyz="0" izz="0.000001"/>
    </inertial>
  </link>
  <!-- Blade 2 -->
  <link name="propeller_back_right_blade2">
    <visual>
      <origin rpy="0 0 0" xyz="-0.045 0 0"/>
      <geometry>
        <box size="0.09 0.008 0.002"/>
      </geometry>
      <material name="propeller_cw"/>
    </visual>
    <collision>
      <origin rpy="0 0 0" xyz="-0.045 0 0"/>
      <geometry>
        <box size="0.09 0.008 0.002"/>
      </geometry>
    </collision>
    <inertial>
      <origin rpy="0 0 0" xyz="-0.045 0 0"/>
      <mass value="0.002"/>
      <inertia ixx="0.000001" ixy="0" ixz="0" iyy="0.000001" iyz="0" izz="0.000001"/>
    </inertial>
  </link>
  <!-- Joint connecting hub to blade 1 -->
  <joint name="propeller_back_right_hub_to_blade1" type="fixed">
    <parent link="propeller_back_right_hub"/>
    <child link="propeller_back_right_blade1"/>
    <origin rpy="0 0 0" xyz="0 0 0"/>
  </joint>
  <joint name="propeller_back_right_hub_to_blade2" type="fixed">
    <parent link="propeller_back_right_hub"/>
    <child link="propeller_back_right_blade2"/>
    <origin rpy="0 0 0" xyz="0 0 0"/>
  </joint>
  <joint name="back_right_motor_to_propeller" type="continuous">
    <parent link="back_right_motor"/>
    <child link="propeller_back_right_hub"/>
    <origin rpy="0 0 0" xyz="0 0 0.12000000000000001"/>
    <axis xyz="0 0 1"/>
    <dynamics damping="0.01" friction="0.001"/>
  </joint>
  <!-- Propeller Hub (center) -->
  <link name="propeller_back_left_hub">
    <visual>
      <origin rpy="0 0 0" xyz="0 0 0"/>
      <geometry>
        <cylinder length="0.005" radius="0.008"/>
      </geometry>
      <material name="gimbal_material">
        <color rgba="0.1 0.1 0.1 1.0"/>
      </material>
    </visual>
    <collision>
      <origin rpy="0 0 0" xyz="0 0 0"/>
      <geometry>
        <cylinder length="0.005" radius="0.008"/>
      </geometry>
    </collision>
    <inertial>
      <origin rpy="0 0 0" xyz="0 0 0"/>
      <mass value="0.05"/>
      <inertia ixx="0.00001" ixy="0" ixz="0" iyy="0.00001" iyz="0" izz="0.00001"/>
    </inertial>
  </link>
  <!-- Blade 1-->
  <link name="propeller_back_left_blade1">
    <visual>
      <origin rpy="0 0 0" xyz="0.045 0 0"/>
      <geometry>
        <box size="0.09 0.008 0.002"/>
      </geometry>
      <material name="propeller_ccw"/>
    </visual>
    <collision>
      <origin rpy="0 0 0" xyz="0.045 0 0"/>
      <geometry>
        <box size="0.09 0.008 0.002"/>
      </geometry>
    </collision>
    <inertial>
      <origin rpy="0 0 0" xyz="0.045 0 0"/>
      <mass value="0.002"/>
      <inertia ixx="0.000001" ixy="0" ixz="0" iyy="0.000001" iyz="0" izz="0.000001"/>
    </inertial>
  </link>
  <!-- Blade 2 -->
  <link name="propeller_back_left_blade2">
    <visual>
      <origin rpy="0 0 0" xyz="-0.045 0 0"/>
      <geometry>
        <box size="0.09 0.008 0.002"/>
      </geometry>
      <material name="propeller_ccw"/>
    </visual>
    <collision>
      <origin rpy="0 0 0" xyz="-0.045 0 0"/>
      <geometry>
        <box size="0.09 0.008 0.002"/>
      </geometry>
    </collision>
    <inertial>
      <origin rpy="0 0 0" xyz="-0.045 0 0"/>
      <mass value="0.002"/>
      <inertia ixx="0.000001" ixy="0" ixz="0" iyy="0.000001" iyz="0" izz="0.000001"/>
    </inertial>
  </link>
  <!-- Joint connecting hub to blade 1 -->
  <joint name="propeller_back_left_hub_to_blade1" type="fixed">
    <parent link="propeller_back_left_hub"/>
    <child link="propeller_back_left_blade1"/>
    <origin rpy="0 0 0" xyz="0 0 0"/>
  </joint>
  <joint name="propeller_back_left_hub_to_blade2" type="fixed">
    <parent link="propeller_back_left_hub"/>
    <child link="propeller_back_left_blade2"/>
    <origin rpy="0 0 0" xyz="0 0 0"/>
  </joint>
  <joint name="back_left_motor_to_propeller" type="continuous">
    <parent link="back_left_motor"/>
    <child link="propeller_back_left_hub"/>
    <origin rpy="0 0 0" xyz="0 0 0.12000000000000001"/>
    <axis xyz="0 0 1"/>
    <dynamics damping="0.01" friction="0.001"/>
  </joint>
  <!-- Propeller Hub (center) -->
  <link name="propeller_front_left_hub">
    <visual>
      <origin rpy="0 0 0" xyz="0 0 0"/>
      <geometry>
        <cylinder length="0.005" radius="0.008"/>
      </geometry>
      <material name="gimbal_material">
        <color rgba="0.1 0.1 0.1 1.0"/>
      </material>
    </visual>
    <collision>
      <origin rpy="0 0 0" xyz="0 0 0"/>
      <geometry>
        <cylinder length="0.005" radius="0.008"/>
      </geometry>
    </collision>
    <inertial>
      <origin rpy="0 0 0" xyz="0 0 0"/>
      <mass value="0.05"/>
      <inertia ixx="0.00001" ixy="0" ixz="0" iyy="0.00001" iyz="0" izz="0.00001"/>
    </inertial>
  </link>
  <!-- Blade 1-->
  <link name="propeller_front_left_blade1">
    <visual>
      <origin rpy="0 0 0" xyz="0.045 0 0"/>
      <geometry>
        <box size="0.09 0.008 0.002"/>
      </geometry>
      <material name="propeller_cw"/>
    </visual>
    <collision>
      <origin rpy="0 0 0" xyz="0.045 0 0"/>
      <geometry>
        <box size="0.09 0.008 0.002"/>
      </geometry>
    </collision>
    <inertial>
      <origin rpy="0 0 0" xyz="0.045 0 0"/>
      <mass value="0.002"/>
      <inertia ixx="0.000001" ixy="0" ixz="0" iyy="0.000001" iyz="0" izz="0.000001"/>
    </inertial>
  </link>
  <!-- Blade 2 -->
  <link name="propeller_front_left_blade2">
    <visual>
      <origin rpy="0 0 0" xyz="-0.045 0 0"/>
      <geometry>
        <box size="0.09 0.008 0.002"/>
      </geometry>
      <material name="propeller_cw"/>
    </visual>
    <collision>
      <origin rpy="0 0 0" xyz="-0.045 0 0"/>
      <geometry>
        <box size="0.09 0.008 0.002"/>
      </geometry>
    </collision>
    <inertial>
      <origin rpy="0 0 0" xyz="-0.045 0 0"/>
      <mass value="0.002"/>
      <inertia ixx="0.000001" ixy="0" ixz="0" iyy="0.000001" iyz="0" izz="0.000001"/>
    </inertial>
  </link>
  <!-- Joint connecting hub to blade 1 -->
  <joint name="propeller_front_left_hub_to_blade1" type="fixed">
    <parent link="propeller_front_left_hub"/>
    <child link="propeller_front_left_blade1"/>
    <origin rpy="0 0 0" xyz="0 0 0"/>
  </joint>
  <joint name="propeller_front_left_hub_to_blade2" type="fixed">
    <parent link="propeller_front_left_hub"/>
    <child link="propeller_front_left_blade2"/>
    <origin rpy="0 0 0" xyz="0 0 0"/>
  </joint>
  <joint name="front_left_motor_to_propeller" type="continuous">
    <parent link="front_left_motor"/>
    <child link="propeller_front_left_hub"/>
    <origin rpy="0 0 0" xyz=" 0 0 0.12000000000000001"/>
    <axis xyz="0 0 1"/>
    <dynamics damping="0.01" friction="0.001"/>
  </joint>
</robot>
